<?xml version='1.0'?>
<sdf version='1.7'>

  <!-- Esta versión es para gazebo Fortress, es decir la versión que se arranca con "ign gazebo"
  Lo que cambia es cómo se usan los plugins de sensores y cmd_vel -->
  <model name='arlo_xolobot'>

    <!-- The base of the arlo robot base: lower and upper decks, and caster wheels (fixed)   -->
    <link name='link_base'>
      <inertial>
        <mass>10</mass>
        <inertia>
          <ixx>0.191043</ixx>
          <ixy>0</ixy>
          <ixz>0</ixz>
          <iyy>0.191043</iyy>
          <iyz>0</iyz>
          <izz>0.331905</izz>
        </inertia>
        <pose frame=''>0 0 0 0 0 0</pose>
      </inertial>
      <pose frame=''>-0.055242 0 0.153337 0 0 0</pose>
      <gravity>1</gravity>
      <self_collide>0</self_collide>
      <kinematic>0</kinematic>
      <enable_wind>0</enable_wind>
      <visual name='visual'>
        <pose frame=''>0 0 0 0 -0 0</pose>
        <geometry>
          <mesh>
            <uri>model://meshes/arlo_base_altura_ok.dae</uri>
            <scale>1 1 1</scale>
          </mesh>
        </geometry>
        <transparency>0</transparency>
        <cast_shadows>1</cast_shadows>
      </visual>
      <collision name='collision_base'>
        <laser_retro>0</laser_retro>
        <max_contacts>10</max_contacts>
        <pose frame=''>0 0 0.070880 0 -0 0</pose>
        <geometry>
          <cylinder>
            <radius>0.288056</radius>
            <length>0.194</length>
          </cylinder>
        </geometry>
        <surface>
          <friction>
            <ode>
              <mu>1</mu>
              <mu2>1</mu2>
              <fdir1>0 0 0</fdir1>
              <slip1>0</slip1>
              <slip2>0</slip2>
            </ode>
            <torsional>
              <coefficient>1</coefficient>
              <patch_radius>0</patch_radius>
              <surface_radius>0</surface_radius>
              <use_patch_radius>1</use_patch_radius>
              <ode>
                <slip>0</slip>
              </ode>
            </torsional>
          </friction>
          <bounce>
            <restitution_coefficient>0</restitution_coefficient>
            <threshold>1e+06</threshold>
          </bounce>
          <contact>
            <collide_without_contact>0</collide_without_contact>
            <collide_without_contact_bitmask>1</collide_without_contact_bitmask>
            <collide_bitmask>1</collide_bitmask>
            <ode>
              <soft_cfm>0</soft_cfm>
              <soft_erp>0.2</soft_erp>
              <kp>1e+13</kp>
              <kd>1</kd>
              <max_vel>0.01</max_vel>
              <min_depth>0</min_depth>
            </ode>
            <bullet>
              <split_impulse>1</split_impulse>
              <split_impulse_penetration_threshold>-0.01</split_impulse_penetration_threshold>
              <soft_cfm>0</soft_cfm>
              <soft_erp>0.2</soft_erp>
              <kp>1e+13</kp>
              <kd>1</kd>
            </bullet>
          </contact>
        </surface>
      </collision>
    </link>

    <!--    The caster wheel: an invisible sphere to simulate de real caster wheel. -->
    <link name='link_caster'>
      <inertial>
        <mass>0.8</mass>
        <inertia>
          <ixx>0.00043452</ixx>
          <ixy>0</ixy>
          <ixz>0</ixz>
          <iyy>0.00043452</iyy>
          <iyz>0</iyz>
          <izz>0.00043452</izz>
        </inertia>
        <pose frame=''>0 0 0 0 -0 0</pose>
      </inertial>
      <pose frame=''>0.167839 0 0.05 0 -0 0</pose>
      <gravity>1</gravity>
      <self_collide>0</self_collide>
      <kinematic>0</kinematic>
      <enable_wind>0</enable_wind>
      <visual name='visual'>
        <pose frame=''>0 0 0 0 0 0</pose>
        <geometry>
          <sphere>
            <radius>0.0466108</radius>
          </sphere>
        </geometry>
        <!--        This makes the sphere invisible -->
        <transparency>1</transparency>
        <cast_shadows>1</cast_shadows>
      </visual>
      <collision name='collision'>
        <laser_retro>0</laser_retro>
        <max_contacts>10</max_contacts>
        <pose frame=''>0 0 0 0 -0 0</pose>
        <geometry>
          <sphere>
            <radius>0.046611</radius>
          </sphere>
        </geometry>
        <surface>
          <friction>
            <ode>
              <mu>1</mu>
              <mu2>1</mu2>
              <fdir1>0 0 0</fdir1>
              <slip1>0</slip1>
              <slip2>0</slip2>
            </ode>
            <torsional>
              <coefficient>1</coefficient>
              <patch_radius>0</patch_radius>
              <surface_radius>0</surface_radius>
              <use_patch_radius>1</use_patch_radius>
              <ode>
                <slip>0</slip>
              </ode>
            </torsional>
          </friction>
          <bounce>
            <restitution_coefficient>0</restitution_coefficient>
            <threshold>1e+06</threshold>
          </bounce>
          <contact>
            <collide_without_contact>0</collide_without_contact>
            <collide_without_contact_bitmask>1</collide_without_contact_bitmask>
            <collide_bitmask>1</collide_bitmask>
            <ode>
              <soft_cfm>0</soft_cfm>
              <soft_erp>0.2</soft_erp>
              <kp>1e+13</kp>
              <kd>1</kd>
              <max_vel>0.01</max_vel>
              <min_depth>0</min_depth>
            </ode>
            <bullet>
              <split_impulse>1</split_impulse>
              <split_impulse_penetration_threshold>-0.01</split_impulse_penetration_threshold>
              <soft_cfm>0</soft_cfm>
              <soft_erp>0.2</soft_erp>
              <kp>1e+13</kp>
              <kd>1</kd>
            </bullet>
          </contact>
        </surface>
      </collision>
    </link>

    <!--    The back caster wheel: an invisible sphere to simulate de real caster wheel. -->
    <link name='link_caster_back'>
      <inertial>
        <mass>0.8</mass>
        <inertia>
          <ixx>0.00043452</ixx>
          <ixy>0</ixy>
          <ixz>0</ixz>
          <iyy>0.00043452</iyy>
          <iyz>0</iyz>
          <izz>0.00043452</izz>
        </inertia>
        <pose frame=''>0 0 0 0 -0 0</pose>
      </inertial>
      <pose frame=''>-0.278 0 0.05 0 -0 0</pose>
      <gravity>1</gravity>
      <self_collide>0</self_collide>
      <kinematic>0</kinematic>
      <enable_wind>0</enable_wind>
      <visual name='visual'>
        <pose frame=''>0 0 0 0 0 0</pose>
        <geometry>
          <sphere>
            <radius>0.0466108</radius>
          </sphere>
        </geometry>
        <!--        This makes the sphere invisible -->
        <transparency>1</transparency>
        <cast_shadows>1</cast_shadows>
      </visual>
      <collision name='collision'>
        <laser_retro>0</laser_retro>
        <max_contacts>10</max_contacts>
        <pose frame=''>0 0 0 0 -0 0</pose>
        <geometry>
          <sphere>
            <radius>0.046611</radius>
          </sphere>
        </geometry>
        <surface>
          <friction>
            <ode>
              <mu>1</mu>
              <mu2>1</mu2>
              <fdir1>0 0 0</fdir1>
              <slip1>0</slip1>
              <slip2>0</slip2>
            </ode>
            <torsional>
              <coefficient>1</coefficient>
              <patch_radius>0</patch_radius>
              <surface_radius>0</surface_radius>
              <use_patch_radius>1</use_patch_radius>
              <ode>
                <slip>0</slip>
              </ode>
            </torsional>
          </friction>
          <bounce>
            <restitution_coefficient>0</restitution_coefficient>
            <threshold>1e+06</threshold>
          </bounce>
          <contact>
            <collide_without_contact>0</collide_without_contact>
            <collide_without_contact_bitmask>1</collide_without_contact_bitmask>
            <collide_bitmask>1</collide_bitmask>
            <ode>
              <soft_cfm>0</soft_cfm>
              <soft_erp>0.2</soft_erp>
              <kp>1e+13</kp>
              <kd>1</kd>
              <max_vel>0.01</max_vel>
              <min_depth>0</min_depth>
            </ode>
            <bullet>
              <split_impulse>1</split_impulse>
              <split_impulse_penetration_threshold>-0.01</split_impulse_penetration_threshold>
              <soft_cfm>0</soft_cfm>
              <soft_erp>0.2</soft_erp>
              <kp>1e+13</kp>
              <kd>1</kd>
            </bullet>
          </contact>
        </surface>
      </collision>
    </link>


    <!--    The left wheel of the base-->
    <link name='link_wheel_left'>
      <inertial>
        <mass>1</mass>
        <inertia>
          <ixx>0.166667</ixx>
          <ixy>0</ixy>
          <ixz>0</ixz>
          <iyy>0.166667</iyy>
          <iyz>0</iyz>
          <izz>0.166667</izz>
        </inertia>
        <pose frame=''>0 0 0 0 -0 0</pose>
      </inertial>
      <pose frame=''>-0.053 0.251767 0.0978 0 -0 0</pose>
      <gravity>1</gravity>
      <self_collide>0</self_collide>
      <kinematic>0</kinematic>
      <enable_wind>0</enable_wind>
      <visual name='visual'>
        <pose frame=''>0 0 0 0 -0 0</pose>
        <geometry>
          <mesh>
            <uri>model://meshes/arlo_wheel_mejorado.obj</uri>
            <scale>1 1 1</scale>
          </mesh>
        </geometry>
        <transparency>0</transparency>
        <cast_shadows>1</cast_shadows>
      </visual>
      <collision name='collision'>
        <laser_retro>0</laser_retro>
        <max_contacts>10</max_contacts>
        <pose frame=''>0 0 0 0 -0 0</pose>
        <geometry>
          <mesh>
            <uri>model://meshes/arlo_wheel_mejorado.obj</uri>
            <scale>1 1 1</scale>
          </mesh>
        </geometry>
        <surface>
          <friction>
            <ode>
              <mu>1</mu>
              <mu2>1</mu2>
              <fdir1>0 0 0</fdir1>
              <slip1>0</slip1>
              <slip2>0</slip2>
            </ode>
            <torsional>
              <coefficient>1</coefficient>
              <patch_radius>0</patch_radius>
              <surface_radius>0</surface_radius>
              <use_patch_radius>1</use_patch_radius>
              <ode>
                <slip>0</slip>
              </ode>
            </torsional>
          </friction>
          <bounce>
            <restitution_coefficient>0</restitution_coefficient>
            <threshold>1e+06</threshold>
          </bounce>
          <contact>
            <collide_without_contact>0</collide_without_contact>
            <collide_without_contact_bitmask>1</collide_without_contact_bitmask>
            <collide_bitmask>1</collide_bitmask>
            <ode>
              <soft_cfm>0</soft_cfm>
              <soft_erp>0.2</soft_erp>
              <kp>1e+13</kp>
              <kd>1</kd>
              <max_vel>0.01</max_vel>
              <min_depth>0</min_depth>
            </ode>
            <bullet>
              <split_impulse>1</split_impulse>
              <split_impulse_penetration_threshold>-0.01</split_impulse_penetration_threshold>
              <soft_cfm>0</soft_cfm>
              <soft_erp>0.2</soft_erp>
              <kp>1e+13</kp>
              <kd>1</kd>
            </bullet>
          </contact>
        </surface>
      </collision>
    </link>

    <!--    The right wheel of the base -->
    <link name='link_wheel_right'>
      <inertial>
        <mass>1</mass>
        <inertia>
          <ixx>0.166667</ixx>
          <ixy>0</ixy>
          <ixz>0</ixz>
          <iyy>0.166667</iyy>
          <iyz>0</iyz>
          <izz>0.166667</izz>
        </inertia>
        <pose frame=''>0 0 0 0 -0 0</pose>
      </inertial>
      <pose frame=''>-0.053 -0.251767 0.0978 0 0 -3.13728</pose>
      <gravity>1</gravity>
      <self_collide>0</self_collide>
      <kinematic>0</kinematic>
      <enable_wind>0</enable_wind>
      <visual name='visual'>
        <pose frame=''>0 0 0 0 -0 0</pose>
        <geometry>
          <mesh>
            <uri>model://meshes/arlo_wheel_mejorado.obj</uri>
            <scale>1 1 1</scale>
          </mesh>
        </geometry>
        <transparency>0</transparency>
        <cast_shadows>1</cast_shadows>
        <material>
          <shader type='pixel' />
          <emissive>0 0 0 1</emissive>
        </material>
      </visual>
      <collision name='collision'>
        <laser_retro>0</laser_retro>
        <max_contacts>10</max_contacts>
        <pose frame=''>0 0 0 0 -0 0</pose>
        <geometry>
          <mesh>
            <uri>model://meshes/arlo_wheel_mejorado.obj</uri>
            <scale>1 1 1</scale>
          </mesh>
        </geometry>
        <surface>
          <friction>
            <ode>
              <mu>1</mu>
              <mu2>1</mu2>
              <fdir1>0 0 0</fdir1>
              <slip1>0</slip1>
              <slip2>0</slip2>
            </ode>
            <torsional>
              <coefficient>1</coefficient>
              <patch_radius>0</patch_radius>
              <surface_radius>0</surface_radius>
              <use_patch_radius>1</use_patch_radius>
              <ode>
                <slip>0</slip>
              </ode>
            </torsional>
          </friction>
          <bounce>
            <restitution_coefficient>0</restitution_coefficient>
            <threshold>1e+06</threshold>
          </bounce>
          <contact>
            <collide_without_contact>0</collide_without_contact>
            <collide_without_contact_bitmask>1</collide_without_contact_bitmask>
            <collide_bitmask>1</collide_bitmask>
            <ode>
              <soft_cfm>0</soft_cfm>
              <soft_erp>0.2</soft_erp>
              <kp>1e+13</kp>
              <kd>1</kd>
              <max_vel>0.01</max_vel>
              <min_depth>0</min_depth>
            </ode>
            <bullet>
              <split_impulse>1</split_impulse>
              <split_impulse_penetration_threshold>-0.01</split_impulse_penetration_threshold>
              <soft_cfm>0</soft_cfm>
              <soft_erp>0.2</soft_erp>
              <kp>1e+13</kp>
              <kd>1</kd>
            </bullet>
          </contact>
        </surface>
      </collision>
    </link>

    <!--    The three PING))) ultrasonic distance sensors (these are fixed with with a JOINT. -->
    <link name='link_sensor_center'>
      <gravity>0</gravity>
      <inertial>
        <mass>0.01</mass>
      </inertial>
      <pose frame=''>0.218715 0 0.17346 0 0 0</pose>
      <sensor name='head_hokuyo_sensor' type='ray'>
        <pose frame=''>0 0 0.0125 3.14159 0 0</pose>
        <visualize>1</visualize>
        <update_rate>30</update_rate>
        <ray>
          <noise>
            <type>gaussian</type>
            <mean>0</mean>
            <stddev>0.001</stddev>
          </noise>
          <scan>
            <horizontal>
              <samples>16</samples>
              <resolution>1</resolution>
              <min_angle>-0.4</min_angle>
              <max_angle>0.4</max_angle>
            </horizontal>
            <vertical>
              <samples>1</samples>
              <min_angle>0</min_angle>
              <max_angle>0</max_angle>
            </vertical>
          </scan>
          <range>
            <min>0.05</min>
            <max>3</max>
            <resolution>0.02</resolution>
          </range>
        </ray>
        <plugin name="gazebo_ros_head_hokuyo_controller" filename="libgazebo_ros_ray_sensor.so">
          <ros>
          <namespace>/arlo/laser/</namespace>
          <remapping>~/out:=scan_center</remapping>
          <!-- <topicName>/arlo/laser/scan_center</topicName> -->
          <!-- <frameName>link_sensor_center</frameName> -->
          </ros>
          <output_type>sensor_msgs/LaserScan</output_type>
        </plugin>
      </sensor>
      <visual name='visual'>
        <pose frame=''>0 0 0 0 -0 0</pose>
        <geometry>
          <mesh>
            <uri>model://meshes/arlo_sensor.dae</uri>
            <scale>1 1 1</scale>
          </mesh>
        </geometry>
      </visual>
      <collision name='collision'>
        <pose frame=''>0 0 0 0 0 0</pose>
        <geometry>
          <mesh>
            <uri>model://meshes/arlo_sensor.dae</uri>
            <scale>1 1 1</scale>
          </mesh>
        </geometry>
      </collision>
    </link>

    <link name='link_sensor_back'>
      <gravity>0</gravity>
      <inertial>
        <mass>0.01</mass>
      </inertial>
      <pose frame=''>-0.325 0 0.17346 0 0 3.14159</pose>
      <sensor name='head_hokuyo_sensor' type='ray'>
        <pose frame=''>0 0 0.0125 3.14159 0 0</pose>
        <visualize>0</visualize>
        <update_rate>30</update_rate>
        <ray>
          <noise>
            <type>gaussian</type>
            <mean>0</mean>
            <stddev>0.001</stddev>
          </noise>
          <scan>
            <horizontal>
              <samples>16</samples>
              <resolution>1</resolution>
              <min_angle>-0.4</min_angle>
              <max_angle>0.4</max_angle>
            </horizontal>
            <vertical>
              <samples>1</samples>
              <min_angle>0</min_angle>
              <max_angle>0</max_angle>
            </vertical>
          </scan>
          <range>
            <min>0.05</min>
            <max>3</max>
            <resolution>0.02</resolution>
          </range>
        </ray>
        <plugin name="gazebo_ros_head_hokuyo_controller" filename="libgazebo_ros_ray_sensor.so">
          <ros>
          <namespace>/arlo/laser/</namespace>
          <remapping>~/out:=scan_back</remapping>
          <!-- <topicName>/arlo/laser/scan_center</topicName> -->
          <!-- <frameName>link_sensor_center</frameName> -->
          </ros>
          <output_type>sensor_msgs/LaserScan</output_type>
        </plugin>
      </sensor>
      <visual name='visual'>
        <pose frame=''>0 0 0 0 -0 0</pose>
        <geometry>
          <mesh>
            <uri>model://meshes/arlo_sensor.dae</uri>
            <scale>1 1 1</scale>
          </mesh>
        </geometry>
      </visual>
      <collision name='collision'>
        <pose frame=''>0 0 0 0 0 0</pose>
        <geometry>
          <mesh>
            <uri>model://meshes/arlo_sensor.dae</uri>
            <scale>1 1 1</scale>
          </mesh>
        </geometry>
      </collision>
    </link>

    <link name='link_sensor_right'>
      <gravity>0</gravity>
      <inertial>
        <mass>0.01</mass>
      </inertial>
      <pose frame=''>0.113899 -0.214883 0.17346 0 0 -0.927292</pose>
      <sensor name='head_hokuyo_sensor' type='ray'>
        <pose frame=''>0 0 0.0125 3.14159 0 0</pose>
        <visualize>1</visualize>
        <update_rate>30</update_rate>
        <ray>
          <noise>
            <type>gaussian</type>
            <mean>0</mean>
            <stddev>0.001</stddev>
          </noise>
          <scan>
            <horizontal>
              <samples>16</samples>
              <resolution>1</resolution>
              <min_angle>-0.4</min_angle>
              <max_angle>0.4</max_angle>
            </horizontal>
            <vertical>
              <samples>1</samples>
              <min_angle>0</min_angle>
              <max_angle>0</max_angle>
            </vertical>
          </scan>
          <range>
            <min>0.05</min>
            <max>3</max>
            <resolution>0.02</resolution>
          </range>
        </ray>
        <plugin name="gazebo_ros_head_hokuyo_controller" filename="libgazebo_ros_ray_sensor.so">
          <ros>
          <namespace>/arlo/laser/</namespace>
          <remapping>~/out:=scan_right</remapping>
          <!-- <topicName>/arlo/laser/scan_center</topicName> -->
          <!-- <frameName>link_sensor_center</frameName> -->
          </ros>
          <output_type>sensor_msgs/LaserScan</output_type>
        </plugin>
      </sensor>
      <visual name='visual'>
        <pose frame=''>0 0 0 0 0 0</pose>
        <geometry>
          <mesh>
            <uri>model://meshes/arlo_sensor.dae</uri>
            <scale>1 1 1</scale>
          </mesh>
        </geometry>
      </visual>
      <collision name='collision'>
        <pose frame=''>0 0 0 0 0 0</pose>
        <geometry>
          <mesh>
            <uri>model://meshes/arlo_sensor.dae</uri>
            <scale>1 1 1</scale>
          </mesh>
        </geometry>
      </collision>
    </link>

    <link name='link_sensor_left'>
      <gravity>0</gravity>
      <inertial>
        <mass>0.01</mass>
      </inertial>
      <pose frame=''>0.113899 0.214883 0.17346 0 0 0.927292</pose>
      <sensor name='head_hokuyo_sensor' type='ray'>
        <pose frame=''>0 0 0.0125 3.14159 0 0</pose>
        <visualize>1</visualize>
        <update_rate>30</update_rate>
        <ray>
          <noise>
            <type>gaussian</type>
            <mean>0</mean>
            <stddev>0.001</stddev>
          </noise>
          <scan>
            <horizontal>
              <samples>16</samples>
              <resolution>1</resolution>
              <min_angle>-0.4</min_angle>
              <max_angle>0.4</max_angle>
            </horizontal>
            <vertical>
              <samples>1</samples>
              <min_angle>0</min_angle>
              <max_angle>0</max_angle>
            </vertical>
          </scan>
          <range>
            <min>0.05</min>
            <max>3</max>
            <resolution>0.02</resolution>
          </range>
        </ray>
        <plugin name="gazebo_ros_head_hokuyo_controller" filename="libgazebo_ros_ray_sensor.so">
          <ros>
          <namespace>/arlo/laser/</namespace>
          <remapping>~/out:=scan_left</remapping>
          <!-- <topicName>/arlo/laser/scan_center</topicName> -->
          <!-- <frameName>link_sensor_center</frameName> -->
          </ros>
          <output_type>sensor_msgs/LaserScan</output_type>
        </plugin>
      </sensor>
      <visual name='visual'>
        <pose frame=''>0 0 0 0 -0 0</pose>
        <geometry>
          <mesh>
            <uri>model://meshes/arlo_sensor.dae</uri>
            <scale>1 1 1</scale>
          </mesh>
        </geometry>
      </visual>
      <collision name='collision'>
        <pose frame=''>0 0 0 0 -0 0</pose>
        <geometry>
          <mesh>
            <uri>model://meshes/arlo_sensor.dae</uri>
            <scale>1 1 1</scale>
          </mesh>
        </geometry>
      </collision>
    </link>

    <!--Joints for keeping fixed the three sonar sensors.    -->
    <joint name='link_base_JOINT_sensor_center' type='fixed'>
      <parent>link_base</parent>
      <child>link_sensor_center</child>
      <pose frame=''>0 0 0 0 -0 0</pose>
      <physics>
        <ode>
          <limit>
            <cfm>0</cfm>
            <erp>0.2</erp>
          </limit>
          <suspension>
            <cfm>0</cfm>
            <erp>0.2</erp>
          </suspension>
        </ode>
      </physics>
    </joint>
    <joint name='link_base_JOINT_sensor_back' type='fixed'>
      <parent>link_base</parent>
      <child>link_sensor_back</child>
      <pose frame=''>0 0 0 0 -0 0</pose>
      <physics>
        <ode>
          <limit>
            <cfm>0</cfm>
            <erp>0.2</erp>
          </limit>
          <suspension>
            <cfm>0</cfm>
            <erp>0.2</erp>
          </suspension>
        </ode>
      </physics>
    </joint>
    <joint name='link_base_JOINT_sensor_right' type='fixed'>
      <parent>link_base</parent>
      <child>link_sensor_right</child>
      <pose frame=''>0 0 0 0 -0 0</pose>
      <physics>
        <ode>
          <limit>
            <cfm>0</cfm>
            <erp>0.2</erp>
          </limit>
          <suspension>
            <cfm>0</cfm>
            <erp>0.2</erp>
          </suspension>
        </ode>
      </physics>
    </joint>
    <joint name='link_base_JOINT_sensor_left' type='fixed'>
      <parent>link_base</parent>
      <child>link_sensor_left</child>
      <pose frame=''>0 0 0 0 -0 0</pose>
      <physics>
        <ode>
          <limit>
            <cfm>0</cfm>
            <erp>0.2</erp>
          </limit>
          <suspension>
            <cfm>0</cfm>
            <erp>0.2</erp>
          </suspension>
        </ode>
      </physics>
    </joint>
    <joint name='link_base_JOINT_caster' type='ball'>
      <parent>link_base</parent>
      <child>link_caster</child>
      <pose frame=''>0 0 0 0 -0 0</pose>
      <physics>
        <ode>
          <limit>
            <cfm>0</cfm>
            <erp>0.2</erp>
          </limit>
          <suspension>
            <cfm>0</cfm>
            <erp>0.2</erp>
          </suspension>
        </ode>
      </physics>
    </joint>
    <joint name='link_base_JOINT_caster_back' type='ball'>
      <parent>link_base</parent>
      <child>link_caster_back</child>
      <pose frame=''>0 0 0 0 -0 0</pose>
      <physics>
        <ode>
          <limit>
            <cfm>0</cfm>
            <erp>0.2</erp>
          </limit>
          <suspension>
            <cfm>0</cfm>
            <erp>0.2</erp>
          </suspension>
        </ode>
      </physics>
    </joint>
    <joint name='link_base_JOINT_wheel_left' type='revolute'>
      <parent>link_base</parent>
      <child>link_wheel_left</child>
      <pose frame=''>0 0 0 0 -0 0</pose>
      <axis>
        <xyz>0 1 0</xyz>
        <use_parent_model_frame>0</use_parent_model_frame>
        <limit>
          <lower>-1.79769e+308</lower>
          <upper>1.79769e+308</upper>
          <effort>-1</effort>
          <velocity>-1</velocity>
        </limit>
        <dynamics>
          <spring_reference>0</spring_reference>
          <spring_stiffness>0</spring_stiffness>
          <damping>0</damping>
          <friction>0</friction>
        </dynamics>
      </axis>
      <physics>
        <ode>
          <limit>
            <cfm>0</cfm>
            <erp>0.2</erp>
          </limit>
          <suspension>
            <cfm>0</cfm>
            <erp>0.2</erp>
          </suspension>
        </ode>
      </physics>
    </joint>
    <joint name='link_base_JOINT_wheel_right' type='revolute'>
      <parent>link_base</parent>
      <child>link_wheel_right</child>
      <pose frame=''>0 0 0 0 -0 0</pose>
      <axis>
        <xyz>0 -1 0</xyz>
        <use_parent_model_frame>0</use_parent_model_frame>
        <limit>
          <lower>-1.79769e+308</lower>
          <upper>1.79769e+308</upper>
          <effort>-1</effort>
          <velocity>-1</velocity>
        </limit>
        <dynamics>
          <spring_reference>0</spring_reference>
          <spring_stiffness>0</spring_stiffness>
          <damping>0</damping>
          <friction>0</friction>
        </dynamics>
      </axis>
      <physics>
        <ode>
          <limit>
            <cfm>0</cfm>
            <erp>0.2</erp>
          </limit>
          <suspension>
            <cfm>0</cfm>
            <erp>0.2</erp>
          </suspension>
        </ode>
      </physics>
    </joint>
    <static>0</static>
    <allow_auto_disable>1</allow_auto_disable>
    
      <plugin
        filename="libignition-gazebo-diff-drive-system.so"
        name="ignition::gazebo::systems::DiffDrive">
        <left_joint>link_base_JOINT_wheel_left</left_joint>
        <right_joint>link_base_JOINT_wheel_right</right_joint>
        <wheel_separation>0.5</wheel_separation>
        <wheel_radius>0.048</wheel_radius>
        <odom_publish_frequency>1</odom_publish_frequency>
        <odom_topic>/odometry_diffdrive_MALO</odom_topic>
        <frame_id>arlo_xolobot/odom</frame_id>
        <child_frame_id>arlo_xolobot</child_frame_id>
        <!-- <tf_topic>tfmio</tf_topic> -->
        <!-- <topic>cmd_vel</topic> -->
        <!-- <max_linear_acceleration>6</max_linear_acceleration>
        <min_linear_acceleration>-3</min_linear_acceleration>
        <max_angular_acceleration>6</max_angular_acceleration>
        <min_angular_acceleration>-3</min_angular_acceleration>
        <max_linear_velocity>6</max_linear_velocity>
        <min_linear_velocity>-3</min_linear_velocity>
        <max_angular_velocity>6</max_angular_velocity>
        <min_angular_velocity>-3</min_angular_velocity> -->
      </plugin>


    <!-- <plugin name="differential_drive_controller" filename="libgazebo_ros_diff_drive.so">
        <alwaysOn>true</alwaysOn>
        <legacyMode>false</legacyMode>
        <updateRate>40</updateRate>
        <leftJoint>link_base_JOINT_wheel_left</leftJoint>
        <rightJoint>link_base_JOINT_wheel_right</rightJoint>
        <wheelSeparation>0.5</wheelSeparation>
        <wheelDiameter>0.096</wheelDiameter>
        <torque>10</torque>
        <commandTopic>cmd_vel</commandTopic>
        <odometryTopic>odom</odometryTopic>
        <odometryFrame>odom</odometryFrame>
        <robotBaseFrame>base_footprint</robotBaseFrame>
    </plugin> -->
    
  </model>
</sdf>
